Workbook
Name Slicer_City: #N/A
Name Slicer_Country: #N/A
Name Slicer_Has_Online_delivery: #N/A
Name Slicer_Has_Table_booking: #N/A
Name Slicer_Price_range: #N/A
Name Slicer_Rating_text: #N/A

Sheet EDA
A2: Restaurant Distribution Analysis
A4: 1. Restaurant Count by Country | E4: 2. Restaurant Count by Top 10 Cities
A5: No. | B5: Country | C5: Restaurant Count | E5: No. | F5: City | G5: Restaurant Count
A6: 1 | B6: {=_xlfn.LET(_xlpm.countries,_xlfn.UNIQUE('[1]Clean Data'!C2:C9552),_xlpm.counts,COUNTIF('[1]Clean Data'!C2:C9552,_xlpm.countries),_xlfn.SORTBY(_xlpm.countries,_xlpm.counts,-1,_xlpm.countries,1))} -> India | C6: =COUNTIF('[1]Clean Data'!C3:C9553,B6) -> 8652 | E6: 1 | F6: {=INDEX(_xlfn.SORTBY(_xlfn.UNIQUE('[1]Clean Data'!D2:D9552),COUNTIF('[1]Clean Data'!D2:D9552,_xlfn.UNIQUE('[1]Clean Data'!D2:D9552)),-1),_xlfn.SEQUENCE(10))} -> New Delhi | G6: =COUNTIF('[1]Clean Data'!D2:D9552,F6) -> 5473
A7: 2 | B7: United States | C7: =COUNTIF('[1]Clean Data'!C4:C9554,B7) -> 434 | E7: 2 | F7: Gurgaon | G7: =COUNTIF('[1]Clean Data'!D3:D9553,F7) -> 1118
A8: 3 | B8: United Kingdom | C8: =COUNTIF('[1]Clean Data'!C5:C9555,B8) -> 80 | E8: 3 | F8: Noida | G8: =COUNTIF('[1]Clean Data'!D4:D9554,F8) -> 1080
A9: 4 | B9: Brazil | C9: =COUNTIF('[1]Clean Data'!C6:C9556,B9) -> 60 | E9: 4 | F9: Faridabad | G9: =COUNTIF('[1]Clean Data'!D5:D9555,F9) -> 251
A10: 5 | B10: South Africa | C10: =COUNTIF('[1]Clean Data'!$C$2:$C$9552,"South Africa") -> 60 | E10: 5 | F10: Ghaziabad | G10: =COUNTIF('[1]Clean Data'!D6:D9556,F10) -> 25
A11: 6 | B11: UAE | C11: =COUNTIF('[1]Clean Data'!C8:C9558,B11) -> 60 | E11: 6 | F11: Albany | G11: =COUNTIF('[1]Clean Data'!D7:D9557,F11) -> 22
A12: 7 | B12: New Zealand | C12: =COUNTIF('[1]Clean Data'!C9:C9559,B12) -> 40 | E12: 7 | F12: Ahmedabad | G12: =COUNTIF('[1]Clean Data'!D8:D9558,F12) -> 21
A13: 8 | B13: Turkey | C13: =COUNTIF('[1]Clean Data'!C10:C9560,B13) -> 34 | E13: 8 | F13: Amritsar | G13: =COUNTIF('[1]Clean Data'!D9:D9559,F13) -> 21
A14: 9 | B14: Australia | C14: =COUNTIF('[1]Clean Data'!C11:C9561,B14) -> 24 | E14: 9 | F14: Bhubaneshwar | G14: =COUNTIF('[1]Clean Data'!D10:D9560,F14) -> 21
A15: 10 | B15: Phillipines | C15: =COUNTIF('[1]Clean Data'!C12:C9562,B15) -> 22 | E15: 10 | F15: Guwahati | G15: =COUNTIF('[1]Clean Data'!D11:D9561,F15) -> 21
A16: 11 | B16: Indonesia | C16: =COUNTIF('[1]Clean Data'!C13:C9563,B16) -> 21
A17: 12 | B17: Qatar | C17: =COUNTIF('[1]Clean Data'!C14:C9564,B17) -> 20
A18: 13 | B18: Singapore | C18: =COUNTIF('[1]Clean Data'!C15:C9565,B18) -> 20
A19: 14 | B19: Sri Lanka | C19: =COUNTIF('[1]Clean Data'!C16:C9566,B19) -> 20
A20: 15 | B20: Canada | C20: =COUNTIF('[1]Clean Data'!C17:C9567,B20) -> 4
A22: Ratings Analysis
A24: 1. Average Ratings by Country | E24: 2. Rating Categories | I24: 3. Top 10 restaurants by Ratings | N24: 4. 10 Most-voted restaurants
A25: No. | B25: Country | C25: Average Rating | E25: No. | F25: Rating Text | G25: Number of Restaurants | I25: No. | J25: Restaurant | K25: Country | L25: Ratings | N25: No. | O25: Restaurant | P25: Country | Q25: Votes
A26: 1 | B26: {=_xlfn.SORTBY(_xlfn.UNIQUE('[1]Clean Data'!$C$2:$C$9552),AVERAGEIF('[1]Clean Data'!$C$2:$C$9552,_xlfn.UNIQUE('[1]Clean Data'!$C$2:$C$9552)),-1)} -> South Africa | C26: =ROUND(AVERAGEIF('[1]Clean Data'!$C$2:$C$9552,B26,'[1]Clean Data'!$P$2:$P$9552),2) -> 4.21 | E26: 1 | F26: {=_xlfn.SORTBY(_xlfn.UNIQUE('[1]Clean Data'!$Q$2:$Q$9552),_xlfn.XMATCH(_xlfn.UNIQUE('[1]Clean Data'!$Q$2:$Q$9552),{"Poor","Average","Good","Very Good","Excellent","Not Rated"}))} -> Poor | G26: =COUNTIF('[1]Clean Data'!$Q$2:$Q$9552,F26) -> 186 | I26: 1 | J26: {=INDEX(_xlfn._xlws.SORT(_xlfn._xlws.FILTER(CHOOSE({1,2,3},'[1]Clean Data'!E2:E9552,'[1]Clean Data'!C2:C9552,'[1]Clean Data'!P2:P9552),'[1]Clean Data'!P2:P9552>=4.5),3,-1),_xlfn.SEQUENCE(10),{1,2,3})} -> Cube - Tasting Kitchen,24 Albrecht Road, Maboneng Precinct, City and Suburban, Inner City | K26: South Africa | L26: 4.9 | N26: 1 | O26: {=INDEX(_xlfn._xlws.SORT(CHOOSE({1,2,3},'[1]Clean Data'!E2:E9552,'[1]Clean Data'!C2:C9552,'[1]Clean Data'!R2:R9552),3,-1),_xlfn.SEQUENCE(10),{1,2,3})} -> Toit,298, Namma Metro Pillar 62, 100 Feet Road, Indiranagar, Bangalore | P26: India | Q26: 10934
A27: 2 | B27: Phillipines | C27: =ROUND(AVERAGEIF('[1]Clean Data'!$C$2:$C$9552,B27,'[1]Clean Data'!$P$2:$P$9552),2) -> 4.47 | E27: 2 | F27: Average | G27: =COUNTIF('[1]Clean Data'!$Q$2:$Q$9552,F27) -> 3737 | I27: 2 | J27: Urbanologi,1 Fox Street, Marshalltown, Inner City, Johannesburg | K27: South Africa | L27: 4.9 | N27: 2 | O27: Truffles,28, 4th 'B' Cross, Koramangala 5th Block, Bangalore | P27: India | Q27: 9667
A28: 3 | B28: Singapore | C28: =ROUND(AVERAGEIF('[1]Clean Data'!$C$2:$C$9552,B28,'[1]Clean Data'!$P$2:$P$9552),2) -> 3.58 | E28: 3 | F28: Good | G28: =COUNTIF('[1]Clean Data'!$Q$2:$Q$9552,F28) -> 2100 | I28: 3 | J28: Restaurant Mosaic @ The Orient,The Orient Boutique Hotel, Crocodile River Valley, Elandsfontein, Near West Park, Pretoria | K28: South Africa | L28: 4.9 | N28: 3 | O28: Hauz Khas Social,9-A & 12, Hauz Khas Village, New Delhi | P28: India | Q28: 7931
A29: 4 | B29: UAE | C29: =ROUND(AVERAGEIF('[1]Clean Data'!$C$2:$C$9552,B29,'[1]Clean Data'!$P$2:$P$9552),2) -> 4.23 | E29: 4 | F29: Very Good | G29: =COUNTIF('[1]Clean Data'!$Q$2:$Q$9552,F29) -> 1079 | I29: 4 | J29: Ooma,Third Floor, Mega Fashion Hall, SM Megamall, Ortigas, Mandaluyong City | K29: Phillipines | L29: 4.9 | N29: 4 | O29: Peter Cat,18A, Park Street, Park Street Area, Kolkata | P29: India | Q29: 7574
A30: 5 | B30: India | C30: =ROUND(AVERAGEIF('[1]Clean Data'!$C$2:$C$9552,B30,'[1]Clean Data'!$P$2:$P$9552),2) -> 2.52 | E30: 5 | F30: Excellent | G30: =COUNTIF('[1]Clean Data'!$Q$2:$Q$9552,F30) -> 301 | I30: 5 | J30: Spiral - Sofitel Philippine Plaza Manila,Plaza Level, Sofitel Philippine Plaza Manila, CCP Complex, Pasay City | K30: Phillipines | L30: 4.9 | N30: 5 | O30: AB's - Absolute Barbecues,90/4, 3rd Floor, Outer Ring Road, Munnekollaly Village, Marathahalli, Bangalore | P30: India | Q30: 6907
A31: 6 | B31: Indonesia | C31: =ROUND(AVERAGEIF('[1]Clean Data'!$C$2:$C$9552,B31,'[1]Clean Data'!$P$2:$P$9552),2) -> 4.3 | E31: 6 | F31: Not rated | G31: =COUNTIF('[1]Clean Data'!$Q$2:$Q$9552,F31) -> 2148 | I31: 6 | J31: Silantro Fil-Mex,75 East Capitol Drive, Kapitolyo, Pasig City | K31: Phillipines | L31: 4.9 | N31: 6 | O31: Barbeque Nation,K1, RDB Boulevard, Block EP & GP, Sector 5, Salt Lake | P31: India | Q31: 5966
A32: 7 | B32: Qatar | C32: =ROUND(AVERAGEIF('[1]Clean Data'!$C$2:$C$9552,B32,'[1]Clean Data'!$P$2:$P$9552),2) -> 4.06 | I32: 7 | J32: Punjab Grill,Venetian Village, Ritz Carlton Abu Dhabi, Grand Canal, Al Maqtaa, Abu Dhabi | K32: UAE | L32: 4.9 | N32: 7 | O32: Big Brewsky,Behind MK Retail, Before WIPRO Corporate Office, Sarjapur Road, Bangalore | P32: India | Q32: 5705
A33: 8 | B33: Sri Lanka | C33: =ROUND(AVERAGEIF('[1]Clean Data'!$C$2:$C$9552,B33,'[1]Clean Data'!$P$2:$P$9552),2) -> 3.87 | I33: 8 | J33: AB's Absolute Barbecues,Mezzanaine Floor, Centurion Star Tower, Deira City Centre Area, Dubai | K33: UAE | L33: 4.9 | N33: 8 | O33: AB's - Absolute Barbecues,Plot 483, 4th Floor, Pemmasani Complex, Bajaj Electronics Building, Near Madhapur Police Station, Road 36, Jubilee Hills, Hyderabad | P33: India | Q33: 5434
A34: 9 | B34: Turkey | C34: =ROUND(AVERAGEIF('[1]Clean Data'!$C$2:$C$9552,B34,'[1]Clean Data'!$P$2:$P$9552),2) -> 4.3 | I34: 9 | J34: Carnival By Tresind,Podium Level, Burj Daman, DIFC, Dubai | K34: UAE | L34: 4.9 | N34: 9 | O34: The Black Pearl,105, 1st A Cross Road, Jyothi Nivas College Road, Koramangala 5th Block, Bangalore | P34: India | Q34: 5385
A35: 10 | B35: United Kingdom | C35: =ROUND(AVERAGEIF('[1]Clean Data'!$C$2:$C$9552,B35,'[1]Clean Data'!$P$2:$P$9552),2) -> 4.09 | I35: 10 | J35: Tresind - Nassima Royal Hotel,Level 2, Nassima Royal Hotel, Sheikh Zayad Road, Trade Centre Area, Dubai | K35: UAE | L35: 4.9 | N35: 10 | O35: BarBQ,43-47-55, Park Street Area, Kolkata | P35: India | Q35: 5288
A36: 11 | B36: United States | C36: =ROUND(AVERAGEIF('[1]Clean Data'!$C$2:$C$9552,B36,'[1]Clean Data'!$P$2:$P$9552),2) -> 4
A37: 12 | B37: Canada | C37: =ROUND(AVERAGEIF('[1]Clean Data'!$C$2:$C$9552,B37,'[1]Clean Data'!$P$2:$P$9552),2) -> 3.58
A38: 13 | B38: Australia | C38: =ROUND(AVERAGEIF('[1]Clean Data'!$C$2:$C$9552,B38,'[1]Clean Data'!$P$2:$P$9552),2) -> 3.66
A39: 14 | B39: New Zealand | C39: =ROUND(AVERAGEIF('[1]Clean Data'!$C$2:$C$9552,B39,'[1]Clean Data'!$P$2:$P$9552),2) -> 4.26
A40: 15 | B40: Brazil | C40: =ROUND(AVERAGEIF('[1]Clean Data'!$C$2:$C$9552,B40,'[1]Clean Data'!$P$2:$P$9552),2) -> 3.76
A42: Pricing Analysis
A44: 1. Average cost for two by Country | E44: 2. Price Ranges
A45: No. | B45: Country | C45: Average | E45: Ranges | F45: Restaurant Count
A46: 1 | B46: {=_xlfn.SORTBY(_xlfn.UNIQUE('[1]Clean Data'!C2:C9552),AVERAGEIF('[1]Clean Data'!$C$2:$C$9552,_xlfn.UNIQUE('[1]Clean Data'!C2:C9552),'[1]Clean Data'!$K$2:$K$9552),-1)} -> Indonesia | C46: =ROUND(AVERAGEIF('[1]Clean Data'!$C$2:$C$9552,B46,'[1]Clean Data'!$K$2:$K$9552),2) -> 281190.48 | E46: {=_xlfn.UNIQUE('[1]Clean Data'!O2:O9552)} -> 3 | F46: =COUNTIF('[1]Clean Data'!$O$2:$O$9552,E46) -> 1408
...

Sheet Insights
A1: KEY INSIGHTS
A3: No. | B3: Area | C3: Key Finding | D3: Result
A4: 1 | B4: Restaurant Distribution | C4: Country with the most restaurants | D4: =_xlfn.XLOOKUP(MAX(EDA!C6:C20),EDA!C6:C20,EDA!B6:B20)&" — "&MAX(EDA!C6:C20)&" restaurants" -> India — 8652 restaurants
A5: 2 | B5: Rating | C5: Country with the highest average rating | D5: {=_xlfn.XLOOKUP(MAX(EDA!C26:C40),EDA!C26:C40,_xlfn.ANCHORARRAY(EDA!B26))&"—"&MAX(EDA!C26:C40)} -> Phillipines—4.47
A6: 3 | B6: Rating | C6: Most common rating category | D6: =_xlfn.XLOOKUP(MAX(EDA!G26:G31),EDA!G26:G31,EDA!C26:C31)&" — "&MAX(EDA!G26:G31)&" restaurants" -> 4.47 — 3737 restaurants
A7: 4 | B7: Pricing | C7: Most common price range | D7: =_xlfn.XLOOKUP(MAX(EDA!F46:F49),EDA!F46:F49,EDA!E46:E49)&" — "&MAX(EDA!F46:F49)&" restaurants" -> 1 — 4444 restaurants
A8: 5 | B8: Pricing | C8: Country with the highest average cost for two | D8: =_xlfn.XLOOKUP(MAX(EDA!C46:C60),EDA!C46:C60,EDA!B46:B60)&" — "&MAX(EDA!C46:C60) -> Indonesia — 281190.48
A9: 6 | B9: Services | C9: Online delivery availability | D9: =_xlfn.XLOOKUP(MAX(EDA!B64:B67),EDA!B64:B67,EDA!A64:A67)&" — "&MAX(EDA!B64:B67)&" restaurants" -> No — 7100 restaurants
A10: 7 | B10: Services | C10: Table booking availability | D10: =_xlfn.XLOOKUP(MAX(EDA!E66:E67),EDA!E66:E67,EDA!D66:D67)&" — "&MAX(EDA!E66:E67)&" restaurants" -> No — 8393 restaurants
A12: TOP 10 CITIES BY RESTAURANT COUNT
A13: Rank | B13: City | C13: Restaurant Count
A14: 1 | B14: {=INDEX(_xlfn.SORTBY(_xlfn.UNIQUE('[1]Clean Data'!D2:D9552),COUNTIF('[1]Clean Data'!D2:D9552,_xlfn.UNIQUE('[1]Clean Data'!D2:D9552)),-1),_xlfn.SEQUENCE(10))} -> New Delhi | C14: {=COUNTIF('[1]Clean Data'!D2:D9552,_xlfn.ANCHORARRAY(B14))} -> 5473
A15: 2 | B15: Gurgaon | C15: 1118
A16: 3 | B16: Noida | C16: 1080
A17: 4 | B17: Faridabad | C17: 251
A18: 5 | B18: Ghaziabad | C18: 25
A19: 6 | B19: Albany | C19: 22
A20: 7 | B20: Ahmedabad | C20: 21
A21: 8 | B21: Amritsar | C21: 21
A22: 9 | B22: Bhubaneshwar | C22: 21
A23: 10 | B23: Guwahati | C23: 21

Sheet Pivot Tables
A1: Pivot Tables
A2: RESTAURANT COUNT BY COUNTRY | D2: AVERAGE RATING BY COUNTRY | G2: CITIES BY RESTAURANT COUNT | J2: Online Delivery vs Table Booking
A4: Row Labels | B4: Count of Restaurant ID | D4: Row Labels | E4: Average of Aggregate rating | G4: Row Labels | H4: Count of Restaurant ID | J4: Service | K4: Yes | L4: No
A5: India | B5: 8652 | D5: Australia | E5: 3.6583333 | G5: New Delhi | H5: 5473 | J5: Online Delivery | K5: =_xlfn.XLOOKUP("Yes",$A$24:$A$27,$B$24:$B$27) -> 2451 | L5: =_xlfn.XLOOKUP("No",$A$24:$A$27,$B$24:$B$27) -> 7100
A6: United States | B6: 434 | D6: Brazil | E6: 3.7633333 | G6: Gurgaon | H6: 1118 | J6: Table Booking | K6: =_xlfn.XLOOKUP("Yes",$A$31:$A$34,$B$31:$B$34) -> 1158 | L6: =_xlfn.XLOOKUP("No",$A$31:$A$34,$B$31:$B$34) -> 8393
A7: United Kingdom | B7: 80 | D7: Canada | E7: 3.575 | G7: Noida | H7: 1080
A8: Brazil | B8: 60 | D8: India | E8: 2.5233241 | G8: Faridabad | H8: 251 | J8: PRICE RANGE DISTRIBUTION
A9: South Africa | B9: 60 | D9: Indonesia | E9: 4.2952381 | G9: Ghaziabad | H9: 25
A10: UAE | B10: 60 | D10: New Zealand | E10: 4.2625 | G10: Albany | H10: 22 | J10: Row Labels | K10: Count of Restaurant ID
A11: New Zealand | B11: 40 | D11: Phillipines | E11: 4.4681818 | G11: Lucknow | H11: 21 | J11: 1 | K11: 4444
A12: Turkey | B12: 34 | D12: Qatar | E12: 4.06 | G12: Amritsar | H12: 21 | J12: 2 | K12: 3113
A13: Australia | B13: 24 | D13: Singapore | E13: 3.575 | G13: Ahmedabad | H13: 21 | J13: 3 | K13: 1408
A14: Phillipines | B14: 22 | D14: South Africa | E14: 4.21 | G14: Bhubaneshwar | H14: 21 | J14: 4 | K14: 586
A15: Indonesia | B15: 21 | D15: Sri Lanka | E15: 3.87 | G15: Guwahati | H15: 21 | J15: Grand Total | K15: 9551
A16: Sri Lanka | B16: 20 | D16: Turkey | E16: 4.3 | G16: Bangalore | H16: 20
A17: Singapore | B17: 20 | D17: UAE | E17: 4.2333333 | G17: Pretoria | H17: 20
A18: Qatar | B18: 20 | D18: United Kingdom | E18: 4.0875 | G18: Nagpur | H18: 20
A19: Canada | B19: 4 | D19: United States | E19: 4.0043779 | G19: Bhopal | H19: 20
A20: Grand Total | B20: 9551 | D20: Grand Total | E20: 2.66637 | G20: Sí£o Paulo | H20: 20
G21: Allahabad | H21: 20
A22: ONLINE DELIVERY AVAILABILITY | D22: RATING CATEGORY DISTRIBUTION | G22: Manchester | H22: 20
G23: Birmingham | H23: 20
A24: Row Labels | B24: Count of Restaurant ID | D24: Row Labels | E24: Count of Restaurant ID | G24: Orlando | H24: 20
A25: No | B25: 7100 | D25: Average | E25: 3737 | G25: Boise | H25: 20
A26: Yes | B26: 2451 | D26: Excellent | E26: 301 | G26: Rest of Hawaii | H26: 20
A27: Grand Total | B27: 9551 | D27: Good | E27: 2100 | G27: Brasí_lia | H27: 20
D28: Not rated | E28: 2148 | G28: Tampa Bay | H28: 20
A29: TABLE BOOKING AVAILABILITY | D29: Poor | E29: 186 | G29: Cape Town | H29: 20
D30: Very Good | E30: 1079 | G30: Ludhiana | H30: 20
A31: Row Labels | B31: Count of Restaurant ID | D31: Grand Total | E31: 9551 | G31: Cedar Rapids/Iowa City | H31: 20
A32: No | B32: 8393 | G32: Mumbai | H32: 20
A33: Yes | B33: 1158 | G33: Chennai | H33: 20
A34: Grand Total | B34: 9551 | G34: Augusta | H34: 20
G35: Coimbatore | H35: 20
G36: Pensacola | H36: 20
G37: Colombo | H37: 20
G38: Pune | H38: 20
G39: Columbus | H39: 20
G40: Savannah | H40: 20
G41: Dalton | H41: 20
...

Sheet Dashboard
B2: RESTAURANT ANALYSIS DASHBOARD
G4: Total Restaurants | J4: Average Rating | M4: Average Cost for Two | P4: Online Delivery | S4: Table Booking
H5: =COUNTA('[1]Clean Data'!$A$2:$A$9552) -> 9551 | J5: =ROUND(AVERAGE('[1]Clean Data'!$P$2:$P$9552),2) -> 2.67 | M5: =ROUND(AVERAGE('[1]Clean Data'!$K$2:$K$9552),2) -> 1199.21 | P5: =COUNTIF('[1]Clean Data'!$N$2:$N$9552,"Yes")/COUNTA('[1]Clean Data'!$A$2:$A$9552) -> 0.25662234 | S5: =COUNTIF('[1]Clean Data'!$M$2:$M$9552,"Yes")/COUNTA('[1]Clean Data'!$A$2:$A$9552) -> 0.12124385
