Workbook

Sheet Zomato Africa
A1: Restaurant ID | B1: Country Code | C1: City | D1: Restaurant Name,Address | E1: Locality | F1: Locality Verbose | G1: Longitude | H1: Latitude | I1: Cuisines
A2: 18395463 | B2: 189 | C2: Cape Town | D2: The Butcher's Wife,15 Belgravia Road, Athlone, Cape Town | E2: Athlone | F2: Athlone, Cape Town | G2: 18.514406 | H2: -33.96466 | I2: Pizza, Grill
A3: 18337845 | B3: 189 | C3: Cape Town | D3: Coco Safar,Ground Floor, Cavendish Square, Claremont, Cape Town | E3: Cavendish Square, Claremont | F3: Cavendish Square, Claremont, Cape Town | G3: 18.464894 | H3: -33.979757 | I3: Cafe, Patisserie
A4: 6401732 | B4: 189 | C4: Cape Town | D4: La Parada,107 Bree Street, CBD, Cape Town | E4: CBD | F4: CBD, Cape Town | G4: 18.417893 | H4: -33.921543 | I4: Spanish, Tapas
A5: 6401060 | B5: 189 | C5: Cape Town | D5: Jason Bakery,185 Bree Street, CBD, Cape Town | E5: CBD | F5: CBD, Cape Town | G5: 18.414571 | H5: -33.924515 | I5: Cafe, Bakery
A6: 6400421 | B6: 189 | C6: Cape Town | D6: Truth Coffee,36 Buitenkant Street, CBD, Cape Town | E6: CBD | F6: CBD, Cape Town | G6: 18.42286 | H6: -33.928496 | I6: Café
A7: 6402177 | B7: 189 | C7: Cape Town | D7: Salushi,25 Protea Road, Claremont, Cape Town | E7: Claremont | F7: Claremont, Cape Town | G7: 18.462423 | H7: -33.978602 | I7: Japanese, Sushi, Asian
A8: 6401198 | B8: 189 | C8: Cape Town | D8: Origin Coffee Roasting,28 Hudson Street, De Waterkant, Cape Town | E8: De Waterkant | F8: De Waterkant, Cape Town | G8: 18.417667 | H8: -33.917333 | I8: Cafe, Bakery, Tea, Vegetarian
A9: 6401054 | B9: 189 | C9: Cape Town | D9: Kloof Street House,30 Kloof Street, Gardens, Cape Town | E9: Gardens | F9: Gardens, Cape Town | G9: 18.4125 | H9: -33.9285 | I9: Mediterranean
A10: 6403291 | B10: 189 | C10: Cape Town | D10: Jerry's Burger Bar,5 Park Road, Kloof Street, Gardens, Cape Town | E10: Gardens | F10: Gardens, Cape Town | G10: 18.410769 | H10: -33.929022 | I10: Burger, American
A11: 6403499 | B11: 189 | C11: Cape Town | D11: Active Sushi,32 Hudson Street, Mirage Building, Green Point, Cape Town | E11: Green Point | F11: Green Point, Cape Town | G11: 18.417566 | H11: -33.917258 | I11: Sushi
A12: 6400191 | B12: 189 | C12: Cape Town | D12: Beluga,The Foundry, Prestwich Street, Green Point, Cape Town | E12: Green Point | F12: Green Point, Cape Town | G12: 18.418015 | H12: -33.912585 | I12: Seafood, Asian, Grill, Sushi
A13: 6404082 | B13: 189 | C13: Cape Town | D13: Rocomamas,107a Main Road, Green Point, Cape Town | E13: Green Point | F13: Green Point, Cape Town | G13: 18.409153 | H13: -33.907776 | I13: Burger, Fast Food, Grill
... A61: 6502857 | B61: 189 | C61: Sandton | D61: Remo's Maximilliano,Waterfall Corner Mall, Corner of Maxwell & Woodmead Drives, Woodmead, Sandton | E61: Waterfall Corner Mall, Midrand | F61: Waterfall Corner Mall, Midrand, Sandton | G61: 28.089878 | H61: -26.02172 | I61: Italian, Pizza

Sheet Zomato Asia
A1: Restaurant ID | B1: Country Code | C1: City | D1: Restaurant Name,Address | E1: Locality | F1: Locality Verbose | G1: Longitude | H1: Latitude | I1: Cuisines
A2: 6317637 | B2: 162 | C2: Makati City | D2: Le Petit Souffle,Third Floor, Century City Mall, Kalayaan Avenue, Poblacion, Makati City | E2: Century City Mall, Poblacion, Makati City | F2: Century City Mall, Poblacion, Makati City, Makati City | G2: 121.02754 | H2: 14.565443 | I2: French, Japanese, Desserts
A3: 6304287 | B3: 162 | C3: Makati City | D3: Izakaya Kikufuji,Little Tokyo, 2277 Chino Roces Avenue, Legaspi Village, Makati City | E3: Little Tokyo, Legaspi Village, Makati City | F3: Little Tokyo, Legaspi Village, Makati City, Makati City | G3: 121.0141 | H3: 14.553708 | I3: Japanese
A4: 6300002 | B4: 162 | C4: Mandaluyong City | D4: Heat - Edsa Shangri-La,Edsa Shangri-La, 1 Garden Way, Ortigas, Mandaluyong City | E4: Edsa Shangri-La, Ortigas, Mandaluyong City | F4: Edsa Shangri-La, Ortigas, Mandaluyong City, Mandaluyong City | G4: 121.05683 | H4: 14.581404 | I4: Seafood, Asian, Filipino, Indian
A5: 6318506 | B5: 162 | C5: Mandaluyong City | D5: Ooma,Third Floor, Mega Fashion Hall, SM Megamall, Ortigas, Mandaluyong City | E5: SM Megamall, Ortigas, Mandaluyong City | F5: SM Megamall, Ortigas, Mandaluyong City, Mandaluyong City | G5: 121.05648 | H5: 14.585318 | I5: Japanese, Sushi
A6: 6314302 | B6: 162 | C6: Mandaluyong City | D6: Sambo Kojin,Third Floor, Mega Atrium, SM Megamall, Ortigas, Mandaluyong City | E6: SM Megamall, Ortigas, Mandaluyong City | F6: SM Megamall, Ortigas, Mandaluyong City, Mandaluyong City | G6: 121.05751 | H6: 14.58445 | I6: Japanese, Korean
A7: 18189371 | B7: 162 | C7: Mandaluyong City | D7: Din Tai Fung,Ground Floor, Mega Fashion Hall, SM Megamall, Ortigas, Mandaluyong City | E7: SM Megamall, Ortigas, Mandaluyong City | F7: SM Megamall, Ortigas, Mandaluyong City, Mandaluyong City | G7: 121.05631 | H7: 14.583764 | I7: Chinese
A8: 6300781 | B8: 162 | C8: Pasay City | D8: Buffet 101,Building K, SM By The Bay, Sunset Boulevard, Mall of Asia Complex (MOA), Pasay City | E8: SM by the Bay, Mall of Asia Complex, Pasay City | F8: SM by the Bay, Mall of Asia Complex, Pasay City, Pasay City | G8: 120.97967 | H8: 14.531333 | I8: Asian, European
A9: 6301290 | B9: 162 | C9: Pasay City | D9: Vikings,Building B, By The Bay, Seaside Boulevard, Mall of Asia Complex (MOA), Pasay City | E9: SM by the Bay, Mall of Asia Complex, Pasay City | F9: SM by the Bay, Mall of Asia Complex, Pasay City, Pasay City | G9: 120.97933 | H9: 14.54 | I9: Seafood, Filipino, Asian, European
A10: 6300010 | B10: 162 | C10: Pasay City | D10: Spiral - Sofitel Philippine Plaza Manila,Plaza Level, Sofitel Philippine Plaza Manila, CCP Complex, Pasay City | E10: Sofitel Philippine Plaza Manila, Pasay City | F10: Sofitel Philippine Plaza Manila, Pasay City, Pasay City | G10: 120.98009 | H10: 14.55299 | I10: European, Asian, Indian
A11: 6314987 | B11: 162 | C11: Pasig City | D11: Locavore,Brixton Technology Center, 10 Brixton Street, Kapitolyo, Pasig City | E11: Kapitolyo | F11: Kapitolyo, Pasig City | G11: 121.05653 | H11: 14.572041 | I11: Filipino
A12: 6309903 | B12: 162 | C12: Pasig City | D12: Silantro Fil-Mex,75 East Capitol Drive, Kapitolyo, Pasig City | E12: Kapitolyo | F12: Kapitolyo, Pasig City | G12: 121.05792 | H12: 14.567689 | I12: Filipino, Mexican
A13: 6309455 | B13: 162 | C13: Pasig City | D13: Mad Mark's Creamery & Good Eats,23 East Capitol Drive, Kapitolyo, Pasig City | E13: Kapitolyo | F13: Kapitolyo, Pasig City | G13: 121.06082 | H13: 14.570849 | I13: American, Ice Cream, Desserts
... A8850: 5927402 | B8850: 208 | C8850: ÛÁstanbul | D8850: Walter's Coffee Roastery,CafeaÛôa Mahallesi, BademaltÛ± Sokak, No 21/B, KadÛ±kí_y, ÛÁstanbul | E8850: Moda | F8850: Moda, ÛÁstanbul | G8850: 29.026016 | H8850: 40.984776 | I8850: Cafe

Sheet Zomato Europe
A1: Restaurant ID | B1: Country Code | C1: City | D1: Restaurant Name,Address | E1: Locality | F1: Locality Verbose | G1: Longitude | H1: Latitude | I1: Cuisines
A2: 6900714 | B2: 215 | C2: Birmingham | D2: Pepe's Piri Piri,254-256 Alum Rock Road, Alum Rock, Birmingham B8 3DD | E2: Alum Rock | F2: Alum Rock, Birmingham | G2: -1.846811 | H2: 52.488557 | I2: Fast Food
A3: 6900883 | B3: 215 | C3: Birmingham | D3: Ju Ju's Cafe,1 Canal Square, Brindleyplace, Birmingham B16 8EH | E3: Brindleyplace | F3: Brindleyplace, Birmingham | G3: -1.918049 | H3: 52.477569 | I3: Cafe, British
A4: 6900374 | B4: 215 | C4: Birmingham | D4: Bank,4 Brindleyplace, Brindleyplace, Birmingham B1 2JB | E4: Brindleyplace, Broad Street | F4: Brindleyplace, Broad Street, Birmingham | G4: -1.914805 | H4: 52.477693 | I4: British, Steak
A5: 6900224 | B5: 215 | C5: Birmingham | D5: Chaophraya,Middle Mall, Bullring Shopping Centre, Special street, Bullring, Birmingham B5 4BH | E5: Bullring Shopping Centre, Southside | F5: Bullring Shopping Centre, Southside, Birmingham | G5: -1.894286 | H5: 52.477633 | I5: Thai
A6: 6900160 | B6: 215 | C6: Birmingham | D6: Handmade Burger Co.,Unit 3, St Martin Square, Bullring Shopping Centre, Bullring, Birmingham B5 4BU | E6: Bullring Shopping Centre, Southside | F6: Bullring Shopping Centre, Southside, Birmingham | G6: -1.894286 | H6: 52.477633 | I6: Burger, American
A7: 6900050 | B7: 215 | C7: Birmingham | D7: Jamie's Italian,Middle Mall, Bullring Shopping Centre, Bullring, Birmingham B5 4BU | E7: Bullring Shopping Centre, Southside | F7: Bullring Shopping Centre, Southside, Birmingham | G7: -1.894286 | H7: 52.477633 | I7: Italian
A8: 6900724 | B8: 215 | C8: Birmingham | D8: Bodega,12 Bennetts Hill, City Centre, Birmingham B2 5RS | E8: City Centre | F8: City Centre, Birmingham | G8: -1.900375 | H8: 52.47969 | I8: Latin American
A9: 6901081 | B9: 215 | C9: Birmingham | D9: San Carlo,4 Temple Street, City Centre, Birmingham B2 5BN | E9: City Centre | F9: City Centre, Birmingham | G9: -1.899133 | H9: 52.480364 | I9: Italian
A10: 6900674 | B10: 215 | C10: Birmingham | D10: Purnell's,55 Cornwall Street, Colmore Business District, Birmingham B3 2DH | E10: Colmore Business District | F10: Colmore Business District, Birmingham | G10: -1.901843 | H10: 52.483643 | I10: Contemporary
A11: 6901062 | B11: 215 | C11: Birmingham | D11: The Warehouse Cafe,54-57 Allison Street, Digbeth, Birmingham B5 5TH | E11: Digbeth | F11: Digbeth, Birmingham | G11: -1.890569 | H11: 52.477388 | I11: British, Cafe
A12: 6900669 | B12: 215 | C12: Birmingham | D12: Fiesta del Asado,229 Hagley Road, Edgbaston, Birmingham B16 9RP | E12: Edgbaston | F12: Edgbaston, Birmingham | G12: -1.938759 | H12: 52.472197 | I12: Latin American, Italian
A13: 6900811 | B13: 215 | C13: Birmingham | D13: Istanbul Restaurant,2 Stockwell Road, Handsworth, Birmingham B21 9RJ | E13: Handsworth | F13: Handsworth, Birmingham | G13: -1.9391667 | H13: 52.514167 | I13: Turkish
... A81: 6800782 | B81: 215 | C81: Manchester | D81: The French by Simon Rogan - The Midland,The Midland, Peter Street, Deansgate, Manchester M60 2DS | E81: The Midland, Deansgate | F81: The Midland, Deansgate, Manchester | G81: -2.245077 | H81: 53.477154 | I81: French

Sheet Zomato NAM
A1: Restaurant ID | B1: Country Code | C1: City | D1: Restaurant Name,Address | E1: Locality | F1: Locality Verbose | G1: Longitude | H1: Latitude | I1: Cuisines
A2: 17284404 | B2: 216 | C2: Albany | D2: Austin's BBQ and Oyster Bar,2820 Meredyth Dr, Albany, GA 31707 | E2: Albany | F2: Albany, Albany | G2: -84.221535 | H2: 31.610387 | I2: BBQ, Burger, Seafood
A3: 17284203 | B3: 216 | C3: Albany | D3: BJ's Country Buffet,2401 Dawson Rd, Albany, GA 31707 | E3: Albany | F3: Albany, Albany | G3: -84.207095 | H3: 31.608743 | I3: American, BBQ
A4: 17284105 | B4: 216 | C4: Albany | D4: Cookie Shoppe,115 N Jackson St, Albany, GA 31701 | E4: Albany | F4: Albany, Albany | G4: -84.154 | H4: 31.5772
A5: 17284302 | B5: 216 | C5: Albany | D5: El Vaquero Mexican Restaurant,2700 Dawson Rd, Albany, GA 31707 | E5: Albany | F5: Albany, Albany | G5: -84.2194 | H5: 31.6158 | I5: Mexican
A6: 17284397 | B6: 216 | C6: Albany | D6: Elements Coffee Co - Northwest,2726 Ledo Rd Ste 10, Albany, GA 31707 | E6: Albany | F6: Albany, Albany | G6: -84.206944 | H6: 31.622412 | I6: Coffee and Tea, Sandwich
A7: 17284211 | B7: 216 | C7: Albany | D7: Pearly's Famous Country Cookng,814 N Slappey Blvd, Albany, GA 31701 | E7: Albany | F7: Albany, Albany | G7: -84.1759 | H7: 31.5882
A8: 17284094 | B8: 216 | C8: Albany | D8: Chick-fil-A,2703 Dawson Rd, Albany, GA 31707 | E8: Albany | F8: Albany, Albany | G8: -84.2193 | H8: 31.616 | I8: Fast Food
A9: 17284409 | B9: 216 | C9: Albany | D9: Guang Zhou Chinese Restaurant,1214 N Westover Blvd, Albany, GA 31707 | E9: Albany | F9: Albany, Albany | G9: -84.209146 | H9: 31.615519 | I9: Asian, Chinese, Vegetarian
A10: 17284139 | B10: 216 | C10: Albany | D10: Harvest Moon,2347 Dawson Road, Albany, GA 31707 | E10: Albany | F10: Albany, Albany | G10: -84.205718 | H10: 31.604905 | I10: Pizza, Bar Food, Sandwich
A11: 17284403 | B11: 216 | C11: Albany | D11: Henry Campbell's Steakhouse,629 N. Westover Blvd, Albany, GA 31707 | E11: Albany | F11: Albany, Albany | G11: -84.223278 | H11: 31.612121 | I11: Steak, Tapas, Bar Food
A12: 17284145 | B12: 216 | C12: Albany | D12: Hong Kong Cafe,2700 Dawson Rd, Albany, GA 31707 | E12: Albany | F12: Albany, Albany | G12: -84.2191 | H12: 31.6156 | I12: Chinese, Seafood, Vegetarian
A13: 17284150 | B13: 216 | C13: Albany | D13: House of China Restaurant II,2526 Dawson Rd Ste A, Albany, GA 31707 | E13: Albany | F13: Albany, Albany | G13: -84.212 | H13: 31.6104 | I13: Chinese
A14: 17284158 | B14: 216 | C14: Albany | D14: Jimmie's Hot Dogs,204 S Jackson St, Albany, GA 31701 | E14: Albany | F14: Albany, Albany | G14: -84.1534 | H14: 31.5751
A15: 17284175 | B15: 216 | C15: Albany | D15: Locos Grill & Pub,547 N Westover Blvd, Albany, GA 31707 | E15: Albany | F15: Albany, Albany | G15: -84.2228 | H15: 31.6077 | I15: American, Burger, Sandwich
A16: 17284179 | B16: 216 | C16: Albany | D16: Longhorn Steakhouse,2733 Dawson Rd, Albany, GA 31707 | E16: Albany | F16: Albany, Albany | G16: -84.2229 | H16: 31.6185 | I16: American, Steak
A17: 17284197 | B17: 216 | C17: Albany | D17: Mikata Japanese Steakhouse,2610 Dawson Rd, Albany, GA 31707 | E17: Albany | F17: Albany, Albany | G17: -84.2164 | H17: 31.6137 | I17: Japanese, Steak, Sushi
A18: 17284241 | B18: 216 | C18: Albany | D18: Shogun Japanese Steak House,629 N Westover Blvd, Albany, GA 31707 | E18: Albany | F18: Albany, Albany | G18: -84.2233 | H18: 31.6118 | I18: Japanese, Steak, Sushi
A19: 17284390 | B19: 216 | C19: Albany | D19: The Catch Seafood Room & Oyster Bar,2332 Whispering Pines Road, Albany, GA 31707 | E19: Albany | F19: Albany, Albany | G19: -84.205025 | H19: 31.605882 | I19: Seafood, Tapas, Bar Food
A20: 17284279 | B20: 216 | C20: Albany | D20: Villa Gargano,1604 N Slappey Blvd, Albany, GA 31701 | E20: Albany | F20: Albany, Albany | G20: -84.1757 | H20: 31.5985 | I20: Italian, Pizza
A21: 17284364 | B21: 216 | C21: Albany | D21: 3 Squares Diner,202 W Franklin St, Sylvester, GA 31791 | E21: Sylvester | F21: Sylvester, Albany | G21: -83.8389 | H21: 31.5308 | I21: American, Breakfast, Diner
A22: 17293281 | B22: 216 | C22: Athens | D22: Last Resort Grill,184 W Clayton St, Athens, GA 30601 | E22: Athens | F22: Athens, Athens | G22: -83.378273 | H22: 33.957999 | I22: American, Southern, Southwestern
A23: 17293301 | B23: 216 | C23: Athens | D23: Mama's Boy Restaurant,197 Oak St, GA 30601 | E23: Athens | F23: Athens, Athens | G23: -83.3654 | H23: 33.9535 | I23: Southern
A24: 17293409 | B24: 216 | C24: Athens | D24: Sr. Sol 1,175 Tallassee Rd, Athens, GA 30606 | E24: Athens | F24: Athens, Athens | G24: -83.4293 | H24: 33.9652 | I24: Mexican
A25: 17293163 | B25: 216 | C25: Athens | D25: Choo Choo Eastside,1055 Gaines School Rd Ste 100, Athens, GA 30605 | E25: Athens | F25: Athens, Athens | G25: -83.3389 | H25: 33.9259 | I25: Japanese, Korean
A26: 17293228 | B26: 216 | C26: Athens | D26: The Grill,171 College Ave, Athens, GA 30601 | E26: Athens | F26: Athens, Athens | G26: -83.375523 | H26: 33.958198 | I26: Breakfast, Burger, Sandwich
... A209: 17375164 | B209: 216 | C209: Gainesville | D209: Bourbon Street Grille,90 Public Sq N, Dahlonega, GA 30533 | E209: Dahlonega | F209: Dahlonega, Gainesville | G209: -83.985353 | H209: 34.532973 | I209: American, Burger, Cajun
A210: 17374552 | B210: 216 | C210: Gainesville | D210: Corkscrew Cafe,51 W Main St, Dahlonega, GA 30533 | E210: Dahlonega | F210: Dahlonega, Gainesville | G210: -83.9858 | H210: 34.5318
A211: 17375078 | B211: 216 | C211: Gainesville | D211: Smokin Gold BBQ,59 E Main St, Dahlonega, GA 30533 | E211: Dahlonega | F211: Dahlonega, Gainesville | G211: -83.983939 | H211: 34.533626 | I211: BBQ
A212: 17375049 | B212: 216 | C212: Gainesville | D212: Hoka-Hoka Japanese Steak & Sushi,617 North Grove Street, Dahlonega, GA 30533 | E212: Dahlonega | F212: Dahlonega, Gainesville | G212: -83.989317 | H212: 34.541044 | I212: Chinese, Japanese, Thai
A213: 17375077 | B213: 216 | C213: Gainesville | D213: Shenanigan's Irish Pub,87 N. Chestatee St., Dahlonega, GA 30533 | E213: Dahlonega | F213: Dahlonega, Gainesville | G213: -83.986119 | H213: 34.533198 | I213: Bar Food, Seafood, Vegetarian
A214: 17375141 | B214: 216 | C214: Gainesville | D214: Fish Tales Lakeside Grille,6330 Mitchell Street, Flowery Branch, GA 30542 | E214: Flowery Branch | F214: Flowery Branch, Gainesville | G214: -83.938024 | H214: 34.183573 | I214: Seafood
A215: 17375198 | B215: 216 | C215: Gainesville | D215: Antebellum,5510 Church Street, Flowery Branch, GA 30542 | E215: Flowery Branch | F215: Flowery Branch, Gainesville | G215: -83.926217 | H215: 34.185707 | I215: American, Southern
A216: 17375180 | B216: 216 | C216: Gainesville | D216: Moonie's Texas Barbecue,5545 Atlanta Highway, Flowery Branch, GA 30542 | E216: Flowery Branch | F216: Flowery Branch, Gainesville | G216: -83.927794 | H216: 34.180043 | I216: BBQ, Sandwich
A217: 17375072 | B217: 216 | C217: Gainesville | D217: Atlanta Highway Seafood Market,227 Atlanta Highway Suite 900, Gainesville, GA 30501 | E217: Gainesville | F217: Gainesville, Gainesville | G217: -83.838457 | H217: 34.285102 | I217: Sandwich, Seafood, Cajun
A218: 17375047 | B218: 216 | C218: Gainesville | D218: Eat at Thai,975 Dawsonville Hwy, Gainesville, GA 30501 | E218: Gainesville | F218: Gainesville, Gainesville | G218: -83.857993 | H218: 34.300182 | I218: Thai
A219: 17375074 | B219: 216 | C219: Gainesville | D219: Smoke House BBQ and Catering,3205 Atlanta Hwy, Atlanta Highway, Gainesville, GA, Gainesville, GA 30507 | E219: Gainesville | F219: Gainesville, Gainesville | G219: -83.860098 | H219: 34.222755 | I219: BBQ
A220: 17374921 | B220: 216 | C220: Gainesville | D220: 2 Dog,317 Spring St SE, Gainesville, GA 30501 | E220: Gainesville | F220: Gainesville, Gainesville | G220: -83.824023 | H220: 34.300567 | I220: American, European, Sandwich
A221: 17374819 | B221: 216 | C221: Gainesville | D221: Longstreet Cafe,1043 Riverside Terrace, Gainesville, GA 30501 | E221: Gainesville | F221: Gainesville, Gainesville | G221: -83.8272 | H221: 34.3166 | I221: Southern
A222: 17375089 | B222: 216 | C222: Gainesville | D222: Re-Cess,118 Bradford St NE, Gainesville, GA 30501 | E222: Gainesville | F222: Gainesville, Gainesville | G222: -83.82686 | H222: 34.300332 | I222: American, Southern
...

Sheet Zomato Oceania
A1: Restaurant ID | B1: Country Code | C1: City | D1: Restaurant Name,Address | E1: Locality | F1: Locality Verbose | G1: Longitude | H1: Latitude | I1: Cuisines
A2: 16611114 | B2: 14 | C2: Gympie | D2: Whitebull Hotel,117 Marsh St, Armidale, NSW | E2: Armidale | F2: Armidale, Armidale | G2: 151.66888 | H2: -30.514717 | I2: Bar Food, Steak
A3: 16608864 | B3: 14 | C3: Taree | D3: Taste of Balingup,63 South Western Hwy, Balingup, WA | E3: Balingup | F3: Balingup, Balingup | G3: 115.98449 | H3: -33.784527 | I3: Modern Australian
A4: 16604911 | B4: 14 | C4: Geelong | D4: Bridge Road Brewers,Old Coach House 50 Ford St, Beechworth, Beechworth, VIC | E4: Beechworth | F4: Beechworth, Beechworth | G4: 146.68585 | H4: -36.360439 | I4: Pizza, Bar Food
A5: 16615894 | B5: 14 | C5: Townsville | D5: The Giggling Goat,14 Beerburrum St, Dicky Beach, QLD | E5: Dicky Beach | F5: Dicky Beach, Dicky Beach | G5: 153.1374 | H5: -26.783576 | I5: Coffee and Tea, Tea, Modern Australian
A6: 16612028 | B6: 14 | C6: Launceston | D6: The Belle General,12 Shelly Beach Rd, East Ballina, NSW | E6: East Ballina | F6: East Ballina, East Ballina | G6: 153.59333 | H6: -28.862663 | I6: Cafe
A7: 16613507 | B7: 14 | C7: Bundaberg | D7: Flaxton Gardens,313 Flaxton Drive, Flaxton, QLD | E7: Flaxton | F7: Flaxton, Flaxton | G7: 152.87715 | H7: -26.652133 | I7: Tea, Modern Australian
A8: 16607969 | B8: 14 | C8: Albany | D8: Bespoke Harvest,16 Grant St, Forrest, VIC | E8: Forrest | F8: Forrest, Forrest | G8: 143.71431 | H8: -38.517292 | I8: Cafe, Australian
A9: 16604358 | B9: 14 | C9: Wollongong | D9: Blue Bean Love Cafe,115 Main Rd, Hepburn Springs, Hepburn Springs, VIC | E9: Hepburn Springs | F9: Hepburn Springs, Hepburn Springs | G9: 144.1387 | H9: -37.312327 | I9: Cafe, Coffee and Tea, Modern Australian
A10: 16604896 | B10: 14 | C10: Armidale | D10: La Trattoria of Lavandula,350 Hepburn-Newstead Road, Hepburn Springs, VIC | E10: Hepburn Springs | F10: Hepburn Springs, Hepburn Springs | G10: 144.11006 | H10: -37.275494 | I10: Italian, Fusion, Cafe
A11: 16612550 | B11: 14 | C11: Murray Bridge | D11: 5 Little Pigs,64 Owen St, Huskisson, NSW | E11: Huskisson | F11: Huskisson, Huskisson | G11: 150.67107 | H11: -35.03887 | I11: Breakfast, Modern Australian
A12: 16606299 | B12: 14 | C12: Portland | D12: Beach Box Cafe,6a Ramsay Blvd, Inverloch, VIC | E12: Inverloch | F12: Inverloch, Inverloch | G12: 145.72871 | H12: -38.634746 | I12: Burger, Coffee and Tea, Modern Australian
A13: 16605794 | B13: 14 | C13: Swan Hill | D13: Funkey Monkey,26 Myer street, Lakes Entrance, VIC | E13: Lakes Entrance | F13: Lakes Entrance, Lakes Entrance | G13: 147.99422 | H13: -37.878386 | I13: Breakfast, Coffee and Tea
... A65: 7100788 | B65: 148 | C65: Wellington City | D65: The Crab Shack,15 Jervois Quay, Queens Wharf, Wellington Central, Wellington City | E65: Wellington Central | F65: Wellington Central, Wellington City | G65: 174.77917 | H65: -41.284833 | I65: Seafood, Kiwi

Sheet Zomato SAM
A1: Restaurant ID | B1: Country Code | C1: City | D1: Restaurant Name,Address | E1: Locality | F1: Locality Verbose | G1: Longitude | H1: Latitude | I1: Cuisines
A2: 6600681 | B2: 30 | C2: Brasí_lia | D2: Chez Michou,SCLN, 208, Bloco A, Loja 30, Asa Norte, Brasí_lia | E2: Asa Norte | F2: Asa Norte, Brasí_lia | G2: -47.881789 | H2: -15.764142 | I2: Fast Food, French
A3: 6601005 | B3: 30 | C3: Brasí_lia | D3: Cafí© Daniel Briand,SCLN 104, Bloco A, Loja 26, Asa Norte, Brasí_lia | E3: Asa Norte | F3: Asa Norte, Brasí_lia | G3: -47.882667 | H3: -15.7775 | I3: Cafe
A4: 6600292 | B4: 30 | C4: Brasí_lia | D4: Casa do Biscoito Mineiro,SCLN 210, Bloco D, Loja 36/48, Asa Norte, Brasí_lia | E4: Asa Norte | F4: Asa Norte, Brasí_lia | G4: -47.882136 | H4: -15.757472 | I4: Bakery
A5: 6600441 | B5: 30 | C5: Brasí_lia | D5: Maori,CLN 110, Bloco D, Loja 28, Asa Norte, Brasí_lia | E5: Asa Norte | F5: Asa Norte, Brasí_lia | G5: -47.888167 | H5: -15.758833 | I5: Brazilian
A6: 6600970 | B6: 30 | C6: Brasí_lia | D6: Pizza íæ Bessa,SCS 214, Bloco C, Loja 40, Asa Sul, Brasí_lia | E6: Asa Sul | F6: Asa Sul, Brasí_lia | G6: -47.915667 | H6: -15.831167 | I6: Pizza
A7: 6600379 | B7: 30 | C7: Brasí_lia | D7: Sushi Loko,SCS 213, Bloco C, Loja 35, Asa Sul, Brasí_lia | E7: Asa Sul | F7: Asa Sul, Brasí_lia | G7: -47.915667 | H7: -15.831 | I7: Japanese
A8: 6600214 | B8: 30 | C8: Brasí_lia | D8: Beirute,CLS 109, Bloco A, Loja 2/6, Asa Sul, Brasí_lia | E8: Asa Sul | F8: Asa Sul, Brasí_lia | G8: -47.9075 | H8: -15.82 | I8: Arabian
A9: 6601218 | B9: 30 | C9: Brasí_lia | D9: New Koto,SCS 212, Bloco B, Loja 26, Asa Sul, Brasí_lia | E9: Asa Sul | F9: Asa Sul, Brasí_lia | G9: -47.910167 | H9: -15.827333 | I9: Japanese
A10: 6600060 | B10: 30 | C10: Brasí_lia | D10: Sandubas Cafí©,Edifí_cio Josí© Severo, SCS 6, Bloco A, Loja 99, Asa Sul, Brasí_lia | E10: Asa Sul | F10: Asa Sul, Brasí_lia | G10: -47.890167 | H10: -15.797 | I10: Brazilian, Cafe
A11: 6600083 | B11: 30 | C11: Brasí_lia | D11: Villa Tevere,CLS 115, Bloco A, Loja 2, Asa Sul, Brasí_lia | E11: Asa Sul | F11: Asa Sul, Brasí_lia | G11: -47.923667 | H11: -15.831333 | I11: Italian
A12: 6601515 | B12: 30 | C12: Brasí_lia | D12: Rovereto,Rua 13 Norte, Lote 4, íguas Claras, Brasí_lia | E12: íguas Claras | F12: íguas Claras, Brasí_lia | G12: -48.019 | H12: -15.837167 | I12: Pizza
A13: 6601361 | B13: 30 | C13: Brasí_lia | D13: Buena Carne,Avenida Araucíçrias, 1325, Loja 19, íguas Claras, Brasí_lia | E13: íguas Claras | F13: íguas Claras, Brasí_lia | G13: -48.019092 | H13: -15.839775 | I13: Bar Food, Brazilian
... A61: 6713772 | B61: 30 | C61: Sí£o Paulo | D61: Sainte Marie Gastronomia,Rua Dom Joí£o Batista da Costa, 70, Vila SíÇnia, Sí£o Paulo | E61: Vila SíÇnia | F61: Vila SíÇnia, Sí£o Paulo | G61: -46.746958 | H61: -23.609207 | I61: Lebanese, Arabian

Sheet KPIs
A1: Restaurant ID | B1: Average Cost for two | C1: Currency | D1: Has Table booking | E1: Has Online delivery | F1: Price range | G1: Aggregate rating | H1: Rating text | I1: Votes
A2: 18395463 | B2: 294 | C2: Rand(R) | D2: No | E2: No | F2: 3 | G2: 3.7 | H2: Good | I2: 22
A3: 18337845 | B3: 300 | C3: Rand(R) | D3: No | E3: No | F3: 4 | G3: 4.1 | H3: Very Good | I3: 88
A4: 6401732 | B4: 360 | C4: Rand(R) | D4: No | E4: No | F4: 4 | G4: 3.7 | H4: Good | I4: 255
A5: 6401060 | B5: 180 | C5: Rand(R) | D5: No | E5: No | F5: 2 | G5: 4.2 | H5: Very Good | I5: 266
A6: 6400421 | B6: 150 | C6: Rand(R) | D6: No | E6: No | F6: 2 | G6: 4.4 | H6: Very Good | I6: 514
A7: 6402177 | B7: 250 | C7: Rand(R) | D7: No | E7: No | F7: 3 | G7: 3.9 | H7: Good | I7: 239
A8: 6401198 | B8: 200 | C8: Rand(R) | D8: No | E8: No | F8: 3 | G8: 4 | H8: Very Good | I8: 185
A9: 6401054 | B9: 350 | C9: Rand(R) | D9: No | E9: No | F9: 4 | G9: 4.5 | H9: Excellent | I9: 356
A10: 6403291 | B10: 250 | C10: Rand(R) | D10: No | E10: No | F10: 3 | G10: 4.4 | H10: Very Good | I10: 281
A11: 6403499 | B11: 250 | C11: Rand(R) | D11: No | E11: No | F11: 3 | G11: 3.8 | H11: Good | I11: 127
A12: 6400191 | B12: 500 | C12: Rand(R) | D12: No | E12: No | F12: 4 | G12: 3.8 | H12: Good | I12: 619
A13: 6404082 | B13: 250 | C13: Rand(R) | D13: No | E13: No | F13: 3 | G13: 3.6 | H13: Good | I13: 131
... A9552: 6713772 | B9552: 120 | C9552: Brazilian Real(R$) | D9552: No | E9552: No | F9552: 4 | G9552: 4.1 | H9552: Very Good | I9552: 11

Sheet Country Master
A1: Country Code | B1: Country
A2: 94 | B2: Indonesia
A3: 94 | B3: Indonesia
A5: 191 | B5: Sri Lanka
A6: 214 | B6: UAE
A7: 94 | B7: Indonesia
A8: 1 | B8: India
A9: 30 | B9: Brazil
A11: 14 | B11: Australia
A12: 208 | B12: Turkey
A13: 189 | B13: South Africa
A14: 1 | B14: India
A15: 216 | B15: United States
... A210: 189 | B210: South Africa

Sheet Data_Quality_Check
A1: Data Quality Check
A3: Sheet | B3: Check | C3: Result | D3: Status
A4: Zomato Africa | B4: Duplicate Restaurant IDs | C4: {=SUMPRODUCT((COUNTIF('Zomato Africa'!A2:A61, 'Zomato Africa'!A2:A61)>1)*1)} -> 0 | D4: =IF(C4=0,"PASS","FAIL") -> PASS
A5: Zomato Asia | B5: Duplicate Restaurant IDs | C5: {=SUMPRODUCT((COUNTIF('Zomato Asia'!A2:A8850, 'Zomato Africa'!A2:A61)>1)*1)} -> 0 | D5: =IF(C5=0,"PASS","FAIL") -> PASS
A6: Zomato Europe | B6: Duplicate Restaurant IDs | C6: {=SUMPRODUCT((COUNTIF('Zomato Europe'!A2:A81, 'Zomato Europe'!A2:A81)>1)*1)} -> 0 | D6: =IF(C6=0,"PASS","FAIL") -> PASS
A7: Zomato NAM | B7: Duplicate Restaurant IDs | C7: {=SUMPRODUCT((COUNTIF('Zomato NAM'!A2:A439, 'Zomato NAM'!A2:A439)>1)*1)} -> 0 | D7: =IF(C7=0,"PASS","FAIL") -> PASS
A8: Zomato Oceania | B8: Duplicate Restaurant IDs | C8: {=SUMPRODUCT((COUNTIF('Zomato Oceania'!A2:A65, 'Zomato Oceania'!A2:A65)>1)*1)} -> 0 | D8: =IF(C8=0,"PASS","FAIL") -> PASS
A9: Zomato SAM | B9: Duplicate Restaurant IDs | C9: {=SUMPRODUCT((COUNTIF('Zomato SAM'!A2:A61, 'Zomato SAM'!A2:A61)>1)*1)} -> 0 | D9: =IF(C9=0,"PASS","FAIL") -> PASS
A10: Zomato Africa | B10: Missing Values | C10: =COUNTBLANK('Zomato Africa'!A2:I61) -> 0 | D10: =IF(C10=0,"PASS","FAIL") -> PASS
A11: Zomato Asia | B11: Missing Values | C11: =COUNTBLANK('Zomato Asia'!A2:I8850) -> 0 | D11: =IF(C11=0,"PASS","FAIL") -> PASS
A12: Zomato Europe | B12: Missing Values | C12: =COUNTBLANK('Zomato Europe'!A2:I81) -> 0 | D12: =IF(C12=0,"PASS","FAIL") -> PASS
A13: Zomato NAM | B13: Missing Values | C13: =COUNTBLANK('Zomato NAM'!A2:I439) -> 9 | D13: =IF(C13=0,"PASS","FAIL") -> FAIL
A14: Zomato Oceania | B14: Missing Values | C14: =COUNTBLANK('Zomato Oceania'!A2:I65) -> 0 | D14: =IF(C14=0,"PASS","FAIL") -> PASS
A15: Zomato SAM | B15: Missing Values | C15: =COUNTBLANK('Zomato SAM'!A2:I61) -> 0 | D15: =IF(C15=0,"PASS","FAIL") -> PASS
A16: Zomato Africa | B16: Invalid Country Codes | C16: {=SUM(--ISNA(VLOOKUP('Zomato Africa'!B2:B61, 'Country Master'!A:B,2,FALSE)))} -> 0 | D16: =IF(C16=0,"PASS","FAIL") -> PASS
A17: Zomato Asia | B17: Invalid Country Codes | C17: {=SUM(--ISNA(VLOOKUP('Zomato Asia'!B2:B8850, 'Country Master'!A:B,2,FALSE)))} -> 0 | D17: =IF(C17=0,"PASS","FAIL") -> PASS
A18: Zomato Europe | B18: Invalid Country Codes | C18: {=SUM(--ISNA(VLOOKUP('Zomato Europe'!B2:B81, 'Country Master'!A:B,2,FALSE)))} -> 0 | D18: =IF(C18=0,"PASS","FAIL") -> PASS
A19: Zomato NAM | B19: Invalid Country Codes | C19: {=SUM(--ISNA(VLOOKUP('Zomato NAM'!B2:B439, 'Country Master'!A:B,2,FALSE)))} -> 0 | D19: =IF(C19=0,"PASS","FAIL") -> PASS
A20: Zomato Oceania | B20: Invalid Country Codes | C20: {=SUM(--ISNA(VLOOKUP('Zomato Oceania'!B2:B65, 'Country Master'!A:B,2,FALSE)))} -> 0 | D20: =IF(C20=0,"PASS","FAIL") -> PASS
A21: Zomato SAM | B21: Invalid Country Codes | C21: {=SUM(--ISNA(VLOOKUP('Zomato SAM'!B2:B61, 'Country Master'!A:B,2,FALSE)))} -> 0 | D21: =IF(C21=0,"PASS","FAIL") -> PASS
A22: Zomato Africa | B22: Referential Integrity | C22: {=SUMPRODUCT(--ISNA(VLOOKUP('Zomato Africa'!A2:A61,KPIs!A2:A9552,1,FALSE)))} -> 0 | D22: =IF(C22=0,"PASS","FAIL") -> PASS
A23: Zomato Asia | B23: Referential Integrity | C23: {=SUMPRODUCT(--ISNA(VLOOKUP('Zomato Asia'!A2:A8850,KPIs!A3:A9553,1,FALSE)))} -> 0 | D23: =IF(C23=0,"PASS","FAIL") -> PASS
A24: Zomato Europe | B24: Referential Integrity | C24: {=SUMPRODUCT(--ISNA(VLOOKUP('Zomato Europe'!A2:A81,KPIs!A4:A9554,1,FALSE)))} -> 0 | D24: =IF(C24=0,"PASS","FAIL") -> PASS
A25: Zomato NAM | B25: Referential Integrity | C25: {=SUMPRODUCT(--ISNA(VLOOKUP('Zomato NAM'!A2:A439,KPIs!A5:A9555,1,FALSE)))} -> 0 | D25: =IF(C25=0,"PASS","FAIL") -> PASS
A26: Zomato Oceania | B26: Referential Integrity | C26: {=SUMPRODUCT(--ISNA(VLOOKUP('Zomato Oceania'!A2:A65,KPIs!A6:A9556,1,FALSE)))} -> 0 | D26: =IF(C26=0,"PASS","FAIL") -> PASS
A27: Zomato SAM | B27: Referential Integrity | C27: {=SUMPRODUCT(--ISNA(VLOOKUP('Zomato SAM'!A2:A61,KPIs!A7:A9557,1,FALSE)))} -> 0 | D27: =IF(C27=0,"PASS","FAIL") -> PASS
A28: KPIs | B28: Invalid Aggregate Rating | C28: =COUNTIF(KPIs!G2:G9552,">5")+COUNTIF(KPIs!G2:G9552,"<0") -> 0 | D28: =IF(C28=0,"PASS","FAIL") -> PASS
A29: KPIs | B29: Price Range Validity | C29: =COUNTIFS(KPIs!F2:F9552,"<>1",KPIs!F2:F9552,"<>2",KPIs!F2:F9552,"<>3",KPIs!F2:F9552,"<>4") -> 0 | D29: =IF(C29=0,"PASS","FAIL") -> PASS
A30: KPIs | B30: Votes | C30: =COUNTIF(KPIs!I2:I9552,"<0") -> 0 | D30: =IF(C30=0,"PASS","FAIL") -> PASS
A31: KPIs | B31: Average Cost for Two | C31: =COUNTIF(KPIs!B2:B9552,"<0") -> 0 | D31: =IF(C31=0,"PASS","FAIL") -> PASS

Sheet Clean Data
A1: Restaurant ID | B1: Country Code | C1: Country | D1: City | E1: Restaurant Name,Address | F1: Locality | G1: Locality Verbose | H1: Longitude | I1: Latitude | J1: Cuisines | K1: Average Cost for two | L1: Currency | M1: Has Table booking | N1: Has Online delivery | O1: Price range | P1: Aggregate rating | Q1: Rating text | R1: Votes
A2: 18395463 | B2: 189 | C2: =_xlfn.XLOOKUP(B2,'Country Master'!A:A,'Country Master'!B:B,"Not Found") -> South Africa | D2: Cape Town | E2: The Butcher's Wife,15 Belgravia Road, Athlone, Cape Town | F2: Athlone | G2: Athlone, Cape Town | H2: 18.514406 | I2: -33.96466 | J2: Pizza, Grill | K2: {=_xlfn.XLOOKUP(A2,KPIs!$A$2:$A$9552,KPIs!$B$2:$I$9552,"Not Found")} -> 294 | L2: Rand(R) | M2: No | N2: No | O2: 3 | P2: 3.7 | Q2: Good | R2: 22
A3: 18337845 | B3: 189 | C3: =_xlfn.XLOOKUP(B3,'Country Master'!A:A,'Country Master'!B:B,"Not Found") -> South Africa | D3: Cape Town | E3: Coco Safar,Ground Floor, Cavendish Square, Claremont, Cape Town | F3: Cavendish Square, Claremont | G3: Cavendish Square, Claremont, Cape Town | H3: 18.464894 | I3: -33.979757 | J3: Cafe, Patisserie | K3: {=_xlfn.XLOOKUP(A3,KPIs!$A$2:$A$9552,KPIs!$B$2:$I$9552,"Not Found")} -> 300 | L3: Rand(R) | M3: No | N3: No | O3: 4 | P3: 4.1 | Q3: Very Good | R3: 88
A4: 6401732 | B4: 189 | C4: =_xlfn.XLOOKUP(B4,'Country Master'!A:A,'Country Master'!B:B,"Not Found") -> South Africa | D4: Cape Town | E4: La Parada,107 Bree Street, CBD, Cape Town | F4: CBD | G4: CBD, Cape Town | H4: 18.417893 | I4: -33.921543 | J4: Spanish, Tapas | K4: {=_xlfn.XLOOKUP(A4,KPIs!$A$2:$A$9552,KPIs!$B$2:$I$9552,"Not Found")} -> 360 | L4: Rand(R) | M4: No | N4: No | O4: 4 | P4: 3.7 | Q4: Good | R4: 255
A5: 6401060 | B5: 189 | C5: =_xlfn.XLOOKUP(B5,'Country Master'!A:A,'Country Master'!B:B,"Not Found") -> South Africa | D5: Cape Town | E5: Jason Bakery,185 Bree Street, CBD, Cape Town | F5: CBD | G5: CBD, Cape Town | H5: 18.414571 | I5: -33.924515 | J5: Cafe, Bakery | K5: {=_xlfn.XLOOKUP(A5,KPIs!$A$2:$A$9552,KPIs!$B$2:$I$9552,"Not Found")} -> 180 | L5: Rand(R) | M5: No | N5: No | O5: 2 | P5: 4.2 | Q5: Very Good | R5: 266
A6: 6400421 | B6: 189 | C6: =_xlfn.XLOOKUP(B6,'Country Master'!A:A,'Country Master'!B:B,"Not Found") -> South Africa | D6: Cape Town | E6: Truth Coffee,36 Buitenkant Street, CBD, Cape Town | F6: CBD | G6: CBD, Cape Town | H6: 18.42286 | I6: -33.928496 | J6: Café | K6: {=_xlfn.XLOOKUP(A6,KPIs!$A$2:$A$9552,KPIs!$B$2:$I$9552,"Not Found")} -> 150 | L6: Rand(R) | M6: No | N6: No | O6: 2 | P6: 4.4 | Q6: Very Good | R6: 514
A7: 6402177 | B7: 189 | C7: =_xlfn.XLOOKUP(B7,'Country Master'!A:A,'Country Master'!B:B,"Not Found") -> South Africa | D7: Cape Town | E7: Salushi,25 Protea Road, Claremont, Cape Town | F7: Claremont | G7: Claremont, Cape Town | H7: 18.462423 | I7: -33.978602 | J7: Japanese, Sushi, Asian | K7: {=_xlfn.XLOOKUP(A7,KPIs!$A$2:$A$9552,KPIs!$B$2:$I$9552,"Not Found")} -> 250 | L7: Rand(R) | M7: No | N7: No | O7: 3 | P7: 3.9 | Q7: Good | R7: 239
A8: 6401198 | B8: 189 | C8: =_xlfn.XLOOKUP(B8,'Country Master'!A:A,'Country Master'!B:B,"Not Found") -> South Africa | D8: Cape Town | E8: Origin Coffee Roasting,28 Hudson Street, De Waterkant, Cape Town | F8: De Waterkant | G8: De Waterkant, Cape Town | H8: 18.417667 | I8: -33.917333 | J8: Cafe, Bakery, Tea, Vegetarian | K8: {=_xlfn.XLOOKUP(A8,KPIs!$A$2:$A$9552,KPIs!$B$2:$I$9552,"Not Found")} -> 200 | L8: Rand(R) | M8: No | N8: No | O8: 3 | P8: 4 | Q8: Very Good | R8: 185
A9: 6401054 | B9: 189 | C9: =_xlfn.XLOOKUP(B9,'Country Master'!A:A,'Country Master'!B:B,"Not Found") -> South Africa | D9: Cape Town | E9: Kloof Street House,30 Kloof Street, Gardens, Cape Town | F9: Gardens | G9: Gardens, Cape Town | H9: 18.4125 | I9: -33.9285 | J9: Mediterranean | K9: {=_xlfn.XLOOKUP(A9,KPIs!$A$2:$A$9552,KPIs!$B$2:$I$9552,"Not Found")} -> 350 | L9: Rand(R) | M9: No | N9: No | O9: 4 | P9: 4.5 | Q9: Excellent | R9: 356
A10: 6403291 | B10: 189 | C10: =_xlfn.XLOOKUP(B10,'Country Master'!A:A,'Country Master'!B:B,"Not Found") -> South Africa | D10: Cape Town | E10: Jerry's Burger Bar,5 Park Road, Kloof Street, Gardens, Cape Town | F10: Gardens | G10: Gardens, Cape Town | H10: 18.410769 | I10: -33.929022 | J10: Burger, American | K10: {=_xlfn.XLOOKUP(A10,KPIs!$A$2:$A$9552,KPIs!$B$2:$I$9552,"Not Found")} -> 250 | L10: Rand(R) | M10: No | N10: No | O10: 3 | P10: 4.4 | Q10: Very Good | R10: 281
A11: 6403499 | B11: 189 | C11: =_xlfn.XLOOKUP(B11,'Country Master'!A:A,'Country Master'!B:B,"Not Found") -> South Africa | D11: Cape Town | E11: Active Sushi,32 Hudson Street, Mirage Building, Green Point, Cape Town | F11: Green Point | G11: Green Point, Cape Town | H11: 18.417566 | I11: -33.917258 | J11: Sushi | K11: {=_xlfn.XLOOKUP(A11,KPIs!$A$2:$A$9552,KPIs!$B$2:$I$9552,"Not Found")} -> 250 | L11: Rand(R) | M11: No | N11: No | O11: 3 | P11: 3.8 | Q11: Good | R11: 127
A12: 6400191 | B12: 189 | C12: =_xlfn.XLOOKUP(B12,'Country Master'!A:A,'Country Master'!B:B,"Not Found") -> South Africa | D12: Cape Town | E12: Beluga,The Foundry, Prestwich Street, Green Point, Cape Town | F12: Green Point | G12: Green Point, Cape Town | H12: 18.418015 | I12: -33.912585 | J12: Seafood, Asian, Grill, Sushi | K12: {=_xlfn.XLOOKUP(A12,KPIs!$A$2:$A$9552,KPIs!$B$2:$I$9552,"Not Found")} -> 500 | L12: Rand(R) | M12: No | N12: No | O12: 4 | P12: 3.8 | Q12: Good | R12: 619
A13: 6404082 | B13: 189 | C13: =_xlfn.XLOOKUP(B13,'Country Master'!A:A,'Country Master'!B:B,"Not Found") -> South Africa | D13: Cape Town | E13: Rocomamas,107a Main Road, Green Point, Cape Town | F13: Green Point | G13: Green Point, Cape Town | H13: 18.409153 | I13: -33.907776 | J13: Burger, Fast Food, Grill | K13: {=_xlfn.XLOOKUP(A13,KPIs!$A$2:$A$9552,KPIs!$B$2:$I$9552,"Not Found")} -> 250 | L13: Rand(R) | M13: No | N13: No | O13: 3 | P13: 3.6 | Q13: Good | R13: 131
... A8992: 17284203 | B8992: 216 | C8992: =_xlfn.XLOOKUP(B8992,'Country Master'!A:A,'Country Master'!B:B,"Not Found") -> United States | D8992: Albany | E8992: BJ's Country Buffet,2401 Dawson Rd, Albany, GA 31707 | F8992: Albany | G8992: Albany, Albany | H8992: -84.207095 | I8992: 31.608743 | J8992: American, BBQ | K8992: {=_xlfn.XLOOKUP(A8992,KPIs!$A$2:$A$9552,KPIs!$B$2:$I$9552,"Not Found")} -> 10 | L8992: Dollar($) | M8992: No | N8992: No | O8992: 1 | P8992: 3.3 | Q8992: Average | R8992: 25
A8993: 17284105 | B8993: 216 | C8993: =_xlfn.XLOOKUP(B8993,'Country Master'!A:A,'Country Master'!B:B,"Not Found") -> United States | D8993: Albany | E8993: Cookie Shoppe,115 N Jackson St, Albany, GA 31701 | F8993: Albany | G8993: Albany, Albany | H8993: -84.154 | I8993: 31.5772 | K8993: {=_xlfn.XLOOKUP(A8993,KPIs!$A$2:$A$9552,KPIs!$B$2:$I$9552,"Not Found")} -> 0 | L8993: Dollar($) | M8993: No | N8993: No | O8993: 1 | P8993: 3.4 | Q8993: Average | R8993: 34
A8994: 17284302 | B8994: 216 | C8994: =_xlfn.XLOOKUP(B8994,'Country Master'!A:A,'Country Master'!B:B,"Not Found") -> United States | D8994: Albany | E8994: El Vaquero Mexican Restaurant,2700 Dawson Rd, Albany, GA 31707 | F8994: Albany | G8994: Albany, Albany | H8994: -84.2194 | I8994: 31.6158 | J8994: Mexican | K8994: {=_xlfn.XLOOKUP(A8994,KPIs!$A$2:$A$9552,KPIs!$B$2:$I$9552,"Not Found")} -> 0 | L8994: Dollar($) | M8994: No | N8994: No | O8994: 1 | P8994: 3.4 | Q8994: Average | R8994: 45
A8995: 17284397 | B8995: 216 | C8995: =_xlfn.XLOOKUP(B8995,'Country Master'!A:A,'Country Master'!B:B,"Not Found") -> United States | D8995: Albany | E8995: Elements Coffee Co - Northwest,2726 Ledo Rd Ste 10, Albany, GA 31707 | F8995: Albany | G8995: Albany, Albany | H8995: -84.206944 | I8995: 31.622412 | J8995: Coffee and Tea, Sandwich | K8995: {=_xlfn.XLOOKUP(A8995,KPIs!$A$2:$A$9552,KPIs!$B$2:$I$9552,"Not Found")} -> 10 | L8995: Dollar($) | M8995: No | N8995: No | O8995: 1 | P8995: 3.4 | Q8995: Average | R8995: 26
A8996: 17284211 | B8996: 216 | C8996: =_xlfn.XLOOKUP(B8996,'Country Master'!A:A,'Country Master'!B:B,"Not Found") -> United States | D8996: Albany | E8996: Pearly's Famous Country Cookng,814 N Slappey Blvd, Albany, GA 31701 | F8996: Albany | G8996: Albany, Albany | H8996: -84.1759 | I8996: 31.5882 | K8996: {=_xlfn.XLOOKUP(A8996,KPIs!$A$2:$A$9552,KPIs!$B$2:$I$9552,"Not Found")} -> 0 | L8996: Dollar($) | M8996: No | N8996: No | O8996: 1 | P8996: 3.4 | Q8996: Average | R8996: 36
A8997: 17284094 | B8997: 216 | C8997: =_xlfn.XLOOKUP(B8997,'Country Master'!A:A,'Country Master'!B:B,"Not Found") -> United States | D8997: Albany | E8997: Chick-fil-A,2703 Dawson Rd, Albany, GA 31707 | F8997: Albany | G8997: Albany, Albany | H8997: -84.2193 | I8997: 31.616 | J8997: Fast Food | K8997: {=_xlfn.XLOOKUP(A8997,KPIs!$A$2:$A$9552,KPIs!$B$2:$I$9552,"Not Found")} -> 10 | L8997: Dollar($) | M8997: No | N8997: No | O8997: 1 | P8997: 3.5 | Q8997: Good | R8997: 67
A8998: 17284409 | B8998: 216 | C8998: =_xlfn.XLOOKUP(B8998,'Country Master'!A:A,'Country Master'!B:B,"Not Found") -> United States | D8998: Albany | E8998: Guang Zhou Chinese Restaurant,1214 N Westover Blvd, Albany, GA 31707 | F8998: Albany | G8998: Albany, Albany | H8998: -84.209146 | I8998: 31.615519 | J8998: Asian, Chinese, Vegetarian | K8998: {=_xlfn.XLOOKUP(A8998,KPIs!$A$2:$A$9552,KPIs!$B$2:$I$9552,"Not Found")} -> 10 | L8998: Dollar($) | M8998: No | N8998: No | O8998: 1 | P8998: 3.9 | Q8998: Good | R8998: 141
A8999: 17284139 | B8999: 216 | C8999: =_xlfn.XLOOKUP(B8999,'Country Master'!A:A,'Country Master'!B:B,"Not Found") -> United States | D8999: Albany | E8999: Harvest Moon,2347 Dawson Road, Albany, GA 31707 | F8999: Albany | G8999: Albany, Albany | H8999: -84.205718 | I8999: 31.604905 | J8999: Pizza, Bar Food, Sandwich | K8999: {=_xlfn.XLOOKUP(A8999,KPIs!$A$2:$A$9552,KPIs!$B$2:$I$9552,"Not Found")} -> 25 | L8999: Dollar($) | M8999: No | N8999: No | O8999: 2 | P8999: 3.7 | Q8999: Good | R8999: 147
A9000: 17284403 | B9000: 216 | C9000: =_xlfn.XLOOKUP(B9000,'Country Master'!A:A,'Country Master'!B:B,"Not Found") -> United States | D9000: Albany | E9000: Henry Campbell's Steakhouse,629 N. Westover Blvd, Albany, GA 31707 | F9000: Albany | G9000: Albany, Albany | H9000: -84.223278 | I9000: 31.612121 | J9000: Steak, Tapas, Bar Food | K9000: {=_xlfn.XLOOKUP(A9000,KPIs!$A$2:$A$9552,KPIs!$B$2:$I$9552,"Not Found")} -> 70 | L9000: Dollar($) | M9000: No | N9000: No | O9000: 4 | P9000: 3.5 | Q9000: Good | R9000: 51
A9001: 17284145 | B9001: 216 | C9001: =_xlfn.XLOOKUP(B9001,'Country Master'!A:A,'Country Master'!B:B,"Not Found") -> United States | D9001: Albany | E9001: Hong Kong Cafe,2700 Dawson Rd, Albany, GA 31707 | F9001: Albany | G9001: Albany, Albany | H9001: -84.2191 | I9001: 31.6156 | J9001: Chinese, Seafood, Vegetarian | K9001: {=_xlfn.XLOOKUP(A9001,KPIs!$A$2:$A$9552,KPIs!$B$2:$I$9552,"Not Found")} -> 25 | L9001: Dollar($) | M9001: No | N9001: No | O9001: 2 | P9001: 3.6 | Q9001: Good | R9001: 88
A9002: 17284150 | B9002: 216 | C9002: =_xlfn.XLOOKUP(B9002,'Country Master'!A:A,'Country Master'!B:B,"Not Found") -> United States | D9002: Albany | E9002: House of China Restaurant II,2526 Dawson Rd Ste A, Albany, GA 31707 | F9002: Albany | G9002: Albany, Albany | H9002: -84.212 | I9002: 31.6104 | J9002: Chinese | K9002: {=_xlfn.XLOOKUP(A9002,KPIs!$A$2:$A$9552,KPIs!$B$2:$I$9552,"Not Found")} -> 10 | L9002: Dollar($) | M9002: No | N9002: No | O9002: 1 | P9002: 3.8 | Q9002: Good | R9002: 153
A9003: 17284158 | B9003: 216 | C9003: =_xlfn.XLOOKUP(B9003,'Country Master'!A:A,'Country Master'!B:B,"Not Found") -> United States | D9003: Albany | E9003: Jimmie's Hot Dogs,204 S Jackson St, Albany, GA 31701 | F9003: Albany | G9003: Albany, Albany | H9003: -84.1534 | I9003: 31.5751 | K9003: {=_xlfn.XLOOKUP(A9003,KPIs!$A$2:$A$9552,KPIs!$B$2:$I$9552,"Not Found")} -> 10 | L9003: Dollar($) | M9003: No | N9003: No | O9003: 1 | P9003: 3.9 | Q9003: Good | R9003: 160
A9004: 17284175 | B9004: 216 | C9004: =_xlfn.XLOOKUP(B9004,'Country Master'!A:A,'Country Master'!B:B,"Not Found") -> United States | D9004: Albany | E9004: Locos Grill & Pub,547 N Westover Blvd, Albany, GA 31707 | F9004: Albany | G9004: Albany, Albany | H9004: -84.2228 | I9004: 31.6077 | J9004: American, Burger, Sandwich | K9004: {=_xlfn.XLOOKUP(A9004,KPIs!$A$2:$A$9552,KPIs!$B$2:$I$9552,"Not Found")} -> 25 | L9004: Dollar($) | M9004: No | N9004: No | O9004: 2 | P9004: 3.5 | Q9004: Good | R9004: 57
A9005: 17284179 | B9005: 216 | C9005: =_xlfn.XLOOKUP(B9005,'Country Master'!A:A,'Country Master'!B:B,"Not Found") -> United States | D9005: Albany | E9005: Longhorn Steakhouse,2733 Dawson Rd, Albany, GA 31707 | F9005: Albany | G9005: Albany, Albany | H9005: -84.2229 | I9005: 31.6185 | J9005: American, Steak | K9005: {=_xlfn.XLOOKUP(A9005,KPIs!$A$2:$A$9552,KPIs!$B$2:$I$9552,"Not Found")} -> 25 | L9005: Dollar($) | M9005: No | N9005: No | O9005: 2 | P9005: 3.5 | Q9005: Good | R9005: 58
A9006: 17284197 | B9006: 216 | C9006: =_xlfn.XLOOKUP(B9006,'Country Master'!A:A,'Country Master'!B:B,"Not Found") -> United States | D9006: Albany | E9006: Mikata Japanese Steakhouse,2610 Dawson Rd, Albany, GA 31707 | F9006: Albany | G9006: Albany, Albany | H9006: -84.2164 | I9006: 31.6137 | J9006: Japanese, Steak, Sushi | K9006: {=_xlfn.XLOOKUP(A9006,KPIs!$A$2:$A$9552,KPIs!$B$2:$I$9552,"Not Found")} -> 40 | L9006: Dollar($) | M9006: No | N9006: No | O9006: 3 | P9006: 3.6 | Q9006: Good | R9006: 115
A9007: 17284241 | B9007: 216 | C9007: =_xlfn.XLOOKUP(B9007,'Country Master'!A:A,'Country Master'!B:B,"Not Found") -> United States | D9007: Albany | E9007: Shogun Japanese Steak House,629 N Westover Blvd, Albany, GA 31707 | F9007: Albany | G9007: Albany, Albany | H9007: -84.2233 | I9007: 31.6118 | J9007: Japanese, Steak, Sushi | K9007: {=_xlfn.XLOOKUP(A9007,KPIs!$A$2:$A$9552,KPIs!$B$2:$I$9552,"Not Found")} -> 40 | L9007: Dollar($) | M9007: No | N9007: No | O9007: 3 | P9007: 3.5 | Q9007: Good | R9007: 51
A9008: 17284390 | B9008: 216 | C9008: =_xlfn.XLOOKUP(B9008,'Country Master'!A:A,'Country Master'!B:B,"Not Found") -> United States | D9008: Albany | E9008: The Catch Seafood Room & Oyster Bar,2332 Whispering Pines Road, Albany, GA 31707 | F9008: Albany | G9008: Albany, Albany | H9008: -84.205025 | I9008: 31.605882 | J9008: Seafood, Tapas, Bar Food | K9008: {=_xlfn.XLOOKUP(A9008,KPIs!$A$2:$A$9552,KPIs!$B$2:$I$9552,"Not Found")} -> 40 | L9008: Dollar($) | M9008: No | N9008: No | O9008: 3 | P9008: 3.8 | Q9008: Good | R9008: 250
A9009: 17284279 | B9009: 216 | C9009: =_xlfn.XLOOKUP(B9009,'Country Master'!A:A,'Country Master'!B:B,"Not Found") -> United States | D9009: Albany | E9009: Villa Gargano,1604 N Slappey Blvd, Albany, GA 31701 | F9009: Albany | G9009: Albany, Albany | H9009: -84.1757 | I9009: 31.5985 | J9009: Italian, Pizza | K9009: {=_xlfn.XLOOKUP(A9009,KPIs!$A$2:$A$9552,KPIs!$B$2:$I$9552,"Not Found")} -> 10 | L9009: Dollar($) | M9009: No | N9009: No | O9009: 1 | P9009: 3.7 | Q9009: Good | R9009: 117
A9010: 17284364 | B9010: 216 | C9010: =_xlfn.XLOOKUP(B9010,'Country Master'!A:A,'Country Master'!B:B,"Not Found") -> United States | D9010: Albany | E9010: 3 Squares Diner,202 W Franklin St, Sylvester, GA 31791 | F9010: Sylvester | G9010: Sylvester, Albany | H9010: -83.8389 | I9010: 31.5308 | J9010: American, Breakfast, Diner | K9010: {=_xlfn.XLOOKUP(A9010,KPIs!$A$2:$A$9552,KPIs!$B$2:$I$9552,"Not Found")} -> 10 | L9010: Dollar($) | M9010: No | N9010: No | O9010: 1 | P9010: 3.4 | Q9010: Average | R9010: 20
A9011: 17293281 | B9011: 216 | C9011: =_xlfn.XLOOKUP(B9011,'Country Master'!A:A,'Country Master'!B:B,"Not Found") -> United States | D9011: Athens | E9011: Last Resort Grill,184 W Clayton St, Athens, GA 30601 | F9011: Athens | G9011: Athens, Athens | H9011: -83.378273 | I9011: 33.957999 | J9011: American, Southern, Southwestern | K9011: {=_xlfn.XLOOKUP(A9011,KPIs!$A$2:$A$9552,KPIs!$B$2:$I$9552,"Not Found")} -> 40 | L9011: Dollar($) | M9011: No | N9011: No | O9011: 3 | P9011: 4.5 | Q9011: Excellent | R9011: 1821
A9012: 17293301 | B9012: 216 | C9012: =_xlfn.XLOOKUP(B9012,'Country Master'!A:A,'Country Master'!B:B,"Not Found") -> United States | D9012: Athens | E9012: Mama's Boy Restaurant,197 Oak St, GA 30601 | F9012: Athens | G9012: Athens, Athens | H9012: -83.3654 | I9012: 33.9535 | J9012: Southern | K9012: {=_xlfn.XLOOKUP(A9012,KPIs!$A$2:$A$9552,KPIs!$B$2:$I$9552,"Not Found")} -> 10 | L9012: Dollar($) | M9012: No | N9012: No | O9012: 1 | P9012: 4.5 | Q9012: Excellent | R9012: 849
A9013: 17293409 | B9013: 216 | C9013: =_xlfn.XLOOKUP(B9013,'Country Master'!A:A,'Country Master'!B:B,"Not Found") -> United States | D9013: Athens | E9013: Sr. Sol 1,175 Tallassee Rd, Athens, GA 30606 | F9013: Athens | G9013: Athens, Athens | H9013: -83.4293 | I9013: 33.9652 | J9013: Mexican | K9013: {=_xlfn.XLOOKUP(A9013,KPIs!$A$2:$A$9552,KPIs!$B$2:$I$9552,"Not Found")} -> 10 | L9013: Dollar($) | M9013: No | N9013: No | O9013: 1 | P9013: 4.6 | Q9013: Excellent | R9013: 917
A9014: 17293163 | B9014: 216 | C9014: =_xlfn.XLOOKUP(B9014,'Country Master'!A:A,'Country Master'!B:B,"Not Found") -> United States | D9014: Athens | E9014: Choo Choo Eastside,1055 Gaines School Rd Ste 100, Athens, GA 30605 | F9014: Athens | G9014: Athens, Athens | H9014: -83.3389 | I9014: 33.9259 | J9014: Japanese, Korean | K9014: {=_xlfn.XLOOKUP(A9014,KPIs!$A$2:$A$9552,KPIs!$B$2:$I$9552,"Not Found")} -> 10 | L9014: Dollar($) | M9014: No | N9014: No | O9014: 1 | P9014: 3.9 | Q9014: Good | R9014: 439
A9015: 17293228 | B9015: 216 | C9015: =_xlfn.XLOOKUP(B9015,'Country Master'!A:A,'Country Master'!B:B,"Not Found") -> United States | D9015: Athens | E9015: The Grill,171 College Ave, Athens, GA 30601 | F9015: Athens | G9015: Athens, Athens | H9015: -83.375523 | I9015: 33.958198 | J9015: Breakfast, Burger, Sandwich | K9015: {=_xlfn.XLOOKUP(A9015,KPIs!$A$2:$A$9552,KPIs!$B$2:$I$9552,"Not Found")} -> 10 | L9015: Dollar($) | M9015: No | N9015: No | O9015: 1 | P9015: 3.7 | Q9015: Good | R9015: 289
... A9198: 17375164 | B9198: 216 | C9198: =_xlfn.XLOOKUP(B9198,'Country Master'!A:A,'Country Master'!B:B,"Not Found") -> United States | D9198: Gainesville | E9198: Bourbon Street Grille,90 Public Sq N, Dahlonega, GA 30533 | F9198: Dahlonega | G9198: Dahlonega, Gainesville | H9198: -83.985353 | I9198: 34.532973 | J9198: American, Burger, Cajun | K9198: {=_xlfn.XLOOKUP(A9198,KPIs!$A$2:$A$9552,KPIs!$B$2:$I$9552,"Not Found")} -> 25 | L9198: Dollar($) | M9198: No | N9198: No | O9198: 2 | P9198: 3.8 | Q9198: Good | R9198: 88
A9199: 17374552 | B9199: 216 | C9199: =_xlfn.XLOOKUP(B9199,'Country Master'!A:A,'Country Master'!B:B,"Not Found") -> United States | D9199: Gainesville | E9199: Corkscrew Cafe,51 W Main St, Dahlonega, GA 30533 | F9199: Dahlonega | G9199: Dahlonega, Gainesville | H9199: -83.9858 | I9199: 34.5318 | K9199: {=_xlfn.XLOOKUP(A9199,KPIs!$A$2:$A$9552,KPIs!$B$2:$I$9552,"Not Found")} -> 40 | L9199: Dollar($) | M9199: No | N9199: No | O9199: 3 | P9199: 3.9 | Q9199: Good | R9199: 209
A9200: 17375078 | B9200: 216 | C9200: =_xlfn.XLOOKUP(B9200,'Country Master'!A:A,'Country Master'!B:B,"Not Found") -> United States | D9200: Gainesville | E9200: Smokin Gold BBQ,59 E Main St, Dahlonega, GA 30533 | F9200: Dahlonega | G9200: Dahlonega, Gainesville | H9200: -83.983939 | I9200: 34.533626 | J9200: BBQ | K9200: {=_xlfn.XLOOKUP(A9200,KPIs!$A$2:$A$9552,KPIs!$B$2:$I$9552,"Not Found")} -> 10 | L9200: Dollar($) | M9200: No | N9200: No | O9200: 1 | P9200: 3.9 | Q9200: Good | R9200: 133
...
